Workbook

Sheet 封页
A9: 航站系统
A11: 测试用例
A13: （Version 1.0）
A23: 深圳运捷迅信息有限公司
A27: 总页数 | C27: 正文 | E27: 附录 | G27: 生效日期
A28: 编制 | E28: 审批

Sheet 历史变更记录
B1: Revision History
B3: 日期 | C3: 版本 | D3: 描述 | E3: 作者 | F3: 审核
B4: 43061 | C4: v1.0 | D4: 创建 | E4: 袁国军

Sheet 测试大纲
A3: 测试大纲
F4: 用例总计 | G4: =SUM(F6:F367) -> 0 | H4: 纳入测试数 | I4: =SUM(G6:G367) -> 0
A5: 模块编号 | B5: 一级大纲 | C5: 二级大纲 | D5: 三级大纲 | E5: 四级大纲 | F5: 用例数 | G5: 纳入测试数 | H5: 是否纳入测试 | I5: 说明
A6: 1 | B6: 人员档案管理 | C6: 人员档案管理
C7: 人员编制管理
C8: 航站编制情况表
A9: 2 | B9: 培训记录管理 | C9: 培训记录管理
C10: 课程管理
C11: 培训明细及数量统计
C12: 培训课程人数统计
A13: 3 | B13: 报备管理 | C13: 离岗报备 | I13: LGBB
C14: 节假日报备 | I14: JRBB
C15: 在岗状态表 | I15: ZGZT
C16: 航站负责人即时查询 | I16: FZCX
C17: 节假日值班表 | I17: JJZB
C18: 离岗报备统计 | I18: BBTJ
A19: 4 | B19: 运行月报告 | C19: 运行月报告查询 | I19: BGCX
C20: 运行月报告问题查询 | I20: WTCX
C21: 运行月报告上报 | I21: BGSB
C22: 问题类别维护 | I22: LBWH
C23: 运行月报告上报率统计 | I23: SBTJ
A24: 5 | B24: 通讯录和站内信 | C24: 通讯录操作 | I24: TXCZ
C25: 站内信 | I25: ZNXJ
A26: 6 | B26: 数据计算与显示 | I26: SJJS
A27: 7 | B27: UI测试 | I27: UITS
A28: 8 | B28: 登录 | I28: XTDL
A29: 9 | B29: 安全性 | I29: XTAQ
A30: 10 | B30: 兼容性 | I30: XTJR
A31: 11 | B31: 性能测试 | I31: XTXN
A32: 制表人/日期：

Sheet 报备管理
B2: 测试用例
S4: 第1轮 | W4: 第2轮 | AA4: 第N轮
S5: 用例条数 | T5: =SUMPRODUCT(($G$11:$G$1991<>"")*($Q$11:$Q$1990<>"删除")) -> #N/A | U5: OK | V5: =SUMPRODUCT(($R$11:$R$1787="是")*(S$11:S$1787=U$5)) -> 0 | W5: 用例条数 | X5: {=SUMPRODUCT(($G$11:$G$1991<>"")*($Q$11:$Q$1990<>"删除"))} -> #N/A | Y5: OK | Z5: =SUMPRODUCT(($R$11:$R$1787="是")*(W$11:W$1787=Y$5)) -> 0 | AA5: 用例条数 | AB5: {=SUMPRODUCT(($G$11:$G$1991<>"")*($Q$11:$Q$1990<>"删除"))} -> #N/A | AC5: OK | AD5: =SUMPRODUCT(($R$11:$R$1787="是")*(AA$11:AA$1787=AC$5)) -> 0
S6: 纳入测试 | T6: {=COUNTIF($R$10:$R$1787,"是")} -> 4 | U6: POK | V6: =SUMPRODUCT(($R$11:$R$1787="是")*(S$11:S$1787=U$6)) -> 0 | W6: 纳入测试 | X6: {=COUNTIF($R$10:$R$1787,"是")} -> 4 | Y6: POK | Z6: =SUMPRODUCT(($R$11:$R$1787="是")*(W$11:W$1787=Y$6)) -> 0 | AA6: 纳入测试 | AB6: {=COUNTIF($R$10:$R$1787,"是")} -> 4 | AC6: POK | AD6: =SUMPRODUCT(($R$11:$R$1787="是")*(AA$11:AA$1787=AC$6)) -> 0
S7: 执行率 | T7: =IF(V5+V6+V7=0,0%,(V5+V6+V7)/(T6)) -> 0 | U7: NG | V7: =SUMPRODUCT(($R$11:$R$1787="是")*(S$11:S$1787=U$7)) -> 0 | W7: 执行率 | X7: =IF(Z5+Z6+Z7=0,0%,(Z5+Z6+Z7)/(X6)) -> 0 | Y7: NG | Z7: =SUMPRODUCT(($R$11:$R$1787="是")*(W$11:W$1787=Y$7)) -> 0 | AA7: 执行率 | AB7: =IF(AD5+AD6+AD7=0,0%,(AD5+AD6+AD7)/(AB6)) -> 0 | AC7: NG | AD7: =SUMPRODUCT(($R$11:$R$1787="是")*(AA$11:AA$1787=AC$7)) -> 0
D8: 测试标识 | E8: 所属项目 | F8: 子系统 | G8: 设计人员 | S8: 通过率 | T8: {=IF(V5=0,0%,V5/(V5+V6+V7))} -> 0 | U8: SKIP | V8: =SUMPRODUCT(($R$11:$R$1787="是")*(S$11:S$1787=U$8)) -> 0 | W8: 通过率 | X8: {=IF(Z5=0,0%,Z5/(Z5+Z6+Z7))} -> 0 | Y8: SKIP | Z8: =SUMPRODUCT(($R$11:$R$1787="是")*(W$11:W$1787=Y$8)) -> 0 | AA8: 通过率 | AB8: {=IF(AD5=0,0%,AD5/(AD5+AD6+AD7))} -> 0 | AC8: SKIP | AD8: =SUMPRODUCT(($R$11:$R$1787="是")*(AA$11:AA$1787=AC$8)) -> 0
D9: Web | E9: 航站二期 | G9: 袁国军 | S9: NT | T9: {=SUMPRODUCT(($R$11:$R$1787="是")*(S$11:S$1787=S9))} -> 0 | U9: 队列中 | V9: {=(T6-V8-V7-V6-V5-T9)} -> 4 | W9: NT | X9: {=SUMPRODUCT(($R$11:$R$1787="是")*(W$11:W$1787=W9))} -> 0 | Y9: 队列中 | Z9: {=(X6-Z8-Z7-Z6-Z5-X9)} -> 4 | AA9: NT | AB9: {=SUMPRODUCT(($R$11:$R$1787="是")*(AA$11:AA$1787=AA9))} -> 0 | AC9: 队列中 | AD9: {=(AB6-AD8-AD7-AD6-AD5-AB9)} -> 4
B10: 序号 | C10: 模块编号 | D10: 一级模块 | E10: 二级模块 | F10: 三级模块 | G10: 用例编号 | H10: 优先级 | I10: 分类 | J10: 用例描述 | K10: 前置条件 | L10: 测试方法和步骤 | M10: 测试数据 | N10: 预期结果 | O10: 校验过程 | P10: 测试工具 | Q10: 修订状态 | R10: 纳入测试 | S10: 测试结果 | T10: 测试版本 | U10: 测试人 | V10: 备注 | W10: 测试结果 | X10: 测试版本 | Y10: 测试人 | Z10: 备注 | AA10: 测试结果 | AB10: 测试版本 | AC10: 测试人 | AD10: 备注 | AE10: 导入结果
B11: =SUBTOTAL(103,$C$11:C11) -> 1 | C11: =测试大纲!$A$13 -> 3 | D11: 报备管理 | E11: 离岗报备 | F11: 离岗报备查询 | G11: =$D$9 & "-"&测试大纲!I$13&"-"&TEXT(SUBTOTAL(103,$C$11:C11),"000") -> Web-LGBB-001 | H11: 高 | I11: 正常系 | J11: 界面元素完整性校验 | K11: 1.登录总部人员身份 2.转到离岗报备查询界面 | N11: 页面元素如下: 1.文本框：航站、员工号、姓名 2.标签：共搜索到X条数据 3.按钮：搜索、离岗报备 4.数据区显示列：员工号、中文姓名、外文姓名、所属航站、事由、离岗时间、天数、状态、提交人、操作 5.数据区按钮：查看、删除 6.日期控件：离岗时间 7.翻页控件
B12: =SUBTOTAL(103,$C$11:C12) -> 2 | C12: =测试大纲!$A$13 -> 3 | D12: 报备管理 | E12: 离岗报备 | F12: 离岗报备查询 | G12: =$D$9 & "-"&测试大纲!I$13&"-"&TEXT(SUBTOTAL(103,$C$11:C12),"000") -> Web-LGBB-002 | H12: 中 | I12: 正常系 | J12: 页面默认数据正确性校验 | K12: 1.登录总部人员身份 2.转到离岗报备查询界面 | N12: 页面所有输入框数据为空、数据展示区也为空并且页码为1
B13: =SUBTOTAL(103,$C$11:C13) -> 3 | C13: =测试大纲!$A$13 -> 3 | D13: 报备管理 | E13: 离岗报备 | F13: 离岗报备查询 | G13: =$D$9 & "-"&测试大纲!I$13&"-"&TEXT(SUBTOTAL(103,$C$11:C13),"000") -> Web-LGBB-003 | H13: 高 | I13: 正常系 | J13: 默认查询数据正确性校验 | K13: 1.登录总部人员身份 2.转到离岗报备查询界面 | L13: 1.点击搜索 | N13: 查询到所有的离岗报备
B14: =SUBTOTAL(103,$C$11:C14) -> 4 | C14: =测试大纲!$A$13 -> 3 | D14: 报备管理 | E14: 离岗报备 | F14: 离岗报备查询 | G14: =$D$9 & "-"&测试大纲!I$13&"-"&TEXT(SUBTOTAL(103,$C$11:C14),"000") -> Web-LGBB-004 | H14: 高 | I14: 正常系 | J14: 航站代码查询校验 | K14: 1.登录航站人员身份 2.转到离岗报备查询界面 | L14: 1.输入航站代码 2.点击搜索 | N14: 筛选记录的航站代码都与测试数据相同 | P14: 自动化 | R14: 是
B15: =SUBTOTAL(103,$C$11:C15) -> 5 | C15: =测试大纲!$A$13 -> 3 | D15: 报备管理 | E15: 离岗报备 | F15: 离岗报备查询 | G15: =$D$9 & "-"&测试大纲!I$13&"-"&TEXT(SUBTOTAL(103,$C$11:C15),"000") -> Web-LGBB-005 | H15: 高 | I15: 正常系 | J15: 员工号查询校验 | K15: 1.总部人员身份 2.转到离岗报备查询界面 | L15: 1.输入员工号 2.点击搜索 | M15: 1340121138 | N15: 筛选记录的员工号与测试数据相同
B16: =SUBTOTAL(103,$C$11:C16) -> 6 | C16: =测试大纲!$A$13 -> 3 | D16: 报备管理 | E16: 离岗报备 | F16: 离岗报备查询 | G16: =$D$9 & "-"&测试大纲!I$13&"-"&TEXT(SUBTOTAL(103,$C$11:C16),"000") -> Web-LGBB-006 | H16: 高 | I16: 正常系 | J16: 离岗时间查询校验 | K16: 1.总部人员身份 2.转到离岗报备查询界面 | L16: 1.选择离岗时间 2.点击搜索 | M16: 2017-10-11~2017-11-12 | N16: 筛选记录的离岗时间至少和测试数据存在部分交集
B17: =SUBTOTAL(103,$C$11:C17) -> 7 | C17: =测试大纲!$A$13 -> 3 | D17: 报备管理 | E17: 离岗报备 | F17: 离岗报备查询 | G17: =$D$9 & "-"&测试大纲!I$13&"-"&TEXT(SUBTOTAL(103,$C$11:C17),"000") -> Web-LGBB-007 | H17: 高 | I17: 正常系 | J17: 中文姓名查询校验 | K17: 1.总部人员身份 2.转到离岗报备查询界面 | L17: 1.姓名框输入中文姓名 2.点击搜索 | M17: 杨国军 | N17: 筛选出对应员工所有的离岗报备
B18: =SUBTOTAL(103,$C$11:C18) -> 8 | C18: =测试大纲!$A$13 -> 3 | D18: 报备管理 | E18: 离岗报备 | F18: 离岗报备查询 | G18: =$D$9 & "-"&测试大纲!I$13&"-"&TEXT(SUBTOTAL(103,$C$11:C18),"000") -> Web-LGBB-008 | H18: 高 | I18: 正常系 | J18: 外文姓名查询校验 | K18: 1.总部人员身份 2.转到离岗报备查询界面 | L18: 1.姓名框输入外文姓名 4.点击搜索 | M18: Jiny | N18: 筛选出对应员工所有的离岗报备
B19: =SUBTOTAL(103,$C$11:C19) -> 9 | C19: =测试大纲!$A$13 -> 3 | D19: 报备管理 | E19: 离岗报备 | F19: 离岗报备查询 | G19: =$D$9 & "-"&测试大纲!I$13&"-"&TEXT(SUBTOTAL(103,$C$11:C19),"000") -> Web-LGBB-009 | H19: 高 | I19: 正常系 | J19: 已审批状态查询校验 | K19: 1.总部人员身份 2.转到离岗报备查询界面 | L19: 1.选择已审批状态 2.点击搜索 | N19: 筛选记录的离岗报备状态都是已审批
B20: =SUBTOTAL(103,$C$11:C20) -> 10 | C20: =测试大纲!$A$13 -> 3 | D20: 报备管理 | E20: 离岗报备 | F20: 离岗报备查询 | G20: =$D$9 & "-"&测试大纲!I$13&"-"&TEXT(SUBTOTAL(103,$C$11:C20),"000") -> Web-LGBB-010 | H20: 高 | I20: 正常系 | J20: 已拒绝状态查询校验 | K20: 1.总部人员身份 2.转到离岗报备查询界面 | L20: 1.选择已拒绝状态 2.点击搜索 | N20: 筛选记录的离岗报备状态都是已拒绝
B21: =SUBTOTAL(103,$C$11:C21) -> 11 | C21: =测试大纲!$A$13 -> 3 | D21: 报备管理 | E21: 离岗报备 | F21: 离岗报备查询 | G21: =$D$9 & "-"&测试大纲!I$13&"-"&TEXT(SUBTOTAL(103,$C$11:C21),"000") -> Web-LGBB-011 | H21: 高 | I21: 异常系 | J21: 不存在航站查询校验 | K21: 1.登录总部人员身份 2.转到离岗报备查询界面 | L21: 1.输入航站代码 2.点击搜索 | M21: PPL | N21: 筛选记录数为0，并弹出相关提示
B22: =SUBTOTAL(103,$C$11:C22) -> 12 | C22: =测试大纲!$A$13 -> 3 | D22: 报备管理 | E22: 离岗报备 | F22: 离岗报备查询 | G22: =$D$9 & "-"&测试大纲!I$13&"-"&TEXT(SUBTOTAL(103,$C$11:C22),"000") -> Web-LGBB-012 | H22: 高 | I22: 异常系 | J22: 不存在员工号查询校验 | K22: 1.总部人员身份 2.转到离岗报备查询界面 | L22: 1.输入员工号 2.点击搜索 | M22: 1235487954 | N22: 筛选记录数为0，并弹出相关提示
B23: =SUBTOTAL(103,$C$11:C23) -> 13 | C23: =测试大纲!$A$13 -> 3 | D23: 报备管理 | E23: 离岗报备 | F23: 离岗报备查询 | G23: =$D$9 & "-"&测试大纲!I$13&"-"&TEXT(SUBTOTAL(103,$C$11:C23),"000") -> Web-LGBB-013 | H23: 高 | I23: 异常系 | J23: 不存在姓名查询校验 | K23: 1.总部人员身份 2.转到离岗报备查询界面 | L23: 1.输入姓名 2.点击“搜索” | M23: 杨杨洋 | N23: 筛选记录数为0，并弹出相关提示
B24: =SUBTOTAL(103,$C$11:C24) -> 14 | C24: =测试大纲!$A$13 -> 3 | D24: 报备管理 | E24: 离岗报备 | F24: 离岗报备查询 | G24: =$D$9 & "-"&测试大纲!I$13&"-"&TEXT(SUBTOTAL(103,$C$11:C24),"000") -> Web-LGBB-014 | H24: 高 | I24: 正常系 | J24: 全条件联合查询校验 | K24: 1.总部人员身份 2.转到离岗报备查询界面 | L24: 1.输入员工号 2.输入航站 3.输入离岗时间 4.输入姓名 5.选择已审批 6.点击搜索 | M24: 1.1340121138 2.PEK 3.2017-10-11~2017-11-12 4.杨国军 | N24: 筛选记录的数据与测试数据相同
B25: =SUBTOTAL(103,$C$11:C25) -> 15 | C25: =测试大纲!$A$13 -> 3 | D25: 报备管理 | E25: 离岗报备 | F25: 离岗报备查询 | G25: =$D$9 & "-"&测试大纲!I$13&"-"&TEXT(SUBTOTAL(103,$C$11:C25),"000") -> Web-LGBB-015 | H25: 高 | I25: 异常系 | J25: 单一离岗时间不关联，其他全条件关联查询，校验是否会返回数据并给与相关提示 | K25: 1.总部人员身份 2.转到离岗报备查询界面 | L25: 1.输入员工号 2.输入姓名 3.输入航站 4.选择离岗时间 5.点击搜索 | M25: 1.1340121138 2.杨国军 3.PEK 4.2017-11-13~2017-11-14 | N25: 筛选记录数为0，并弹出相关提示
B26: =SUBTOTAL(103,$C$11:C26) -> 16 | C26: =测试大纲!$A$13 -> 3 | D26: 报备管理 | E26: 离岗报备 | F26: 离岗报备查询 | G26: =$D$9 & "-"&测试大纲!I$13&"-"&TEXT(SUBTOTAL(103,$C$11:C26),"000") -> Web-LGBB-016 | H26: 高 | I26: 异常系 | J26: 单一姓名不关联，其他全条件关联查询，校验是否会返回数据并给与相关提示 | K26: 1.总部人员身份 2.转到离岗报备查询界面 | L26: 1.输入员工号 2.输入姓名 3.输入航站 4.选择离岗时间 5.点击搜索 | M26: 1.1340121138 2.杨开运 3.PEK 4.2017-10-11~2017-11-12 | N26: 筛选记录数为0，并弹出相关提示
B27: =SUBTOTAL(103,$C$11:C27) -> 17 | C27: =测试大纲!$A$13 -> 3 | D27: 报备管理 | E27: 离岗报备 | F27: 离岗报备查询 | G27: =$D$9 & "-"&测试大纲!I$13&"-"&TEXT(SUBTOTAL(103,$C$11:C27),"000") -> Web-LGBB-017 | H27: 高 | I27: 异常系 | J27: 单一航站不关联，其他全条件关联查询，校验是否会返回数据并给与相关提示 | K27: 1.总部人员身份 2.转到离岗报备查询界面 | L27: 1.输入员工号 2.输入姓名 3.输入航站 4.选择离岗时间 5.点击搜索 | M27: 1.1340121138 2.杨国军 3.PPL 4.2017-10-11~2017-11-12 | N27: 筛选记录数为0，并弹出相关提示
B28: =SUBTOTAL(103,$C$11:C28) -> 18 | C28: =测试大纲!$A$13 -> 3 | D28: 报备管理 | E28: 离岗报备 | F28: 离岗报备查询 | G28: =$D$9 & "-"&测试大纲!I$13&"-"&TEXT(SUBTOTAL(103,$C$11:C28),"000") -> Web-LGBB-018 | H28: 高 | I28: 异常系 | J28: 单一员工号不关联，其他全条件关联查询，校验是否会返回数据并给与相关提示 | K28: 1.总部人员身份 2.转到离岗报备查询界面 | L28: 1.输入员工号 2.输入姓名 3.输入航站 4.选择离岗时间 5.点击搜索 | M28: 1.1235487954 2.杨国军 3.PEK 4.2017-10-11~2017-11-12 | N28: 筛选记录数为0，并弹出相关提示
B29: =SUBTOTAL(103,$C$11:C29) -> 19 | C29: =测试大纲!$A$13 -> 3 | D29: 报备管理 | E29: 离岗报备 | F29: 离岗报备查询 | G29: =$D$9 & "-"&测试大纲!I$13&"-"&TEXT(SUBTOTAL(103,$C$11:C29),"000") -> Web-LGBB-019 | H29: 中 | I29: 正常系 | J29: 员工号模糊查询校验 | K29: 1.总部人员身份 2.转到离岗报备查询界面 | L29: 1.输入员工号 2.点击搜索 | M29: 13 | N29: 筛选记录的员工号前两位数字和测试数据相同
B30: =SUBTOTAL(103,$C$11:C30) -> 20 | C30: =测试大纲!$A$13 -> 3 | D30: 报备管理 | E30: 离岗报备 | F30: 离岗报备查询 | G30: =$D$9 & "-"&测试大纲!I$13&"-"&TEXT(SUBTOTAL(103,$C$11:C30),"000") -> Web-LGBB-020 | H30: 中 | I30: 正常系 | J30: 姓名模糊查询校验 | K30: 1.总部人员身份 2.转到离岗报备查询界面 | L30: 1.输入姓名 2.点击搜索 | M30: 杨 | N30: 筛选记录的姓名开头都与和测试数据相同
B31: =SUBTOTAL(103,$C$11:C31) -> 21 | C31: =测试大纲!$A$13 -> 3 | D31: 报备管理 | E31: 离岗报备 | F31: 离岗报备查询 | G31: =$D$9 & "-"&测试大纲!I$13&"-"&TEXT(SUBTOTAL(103,$C$11:C31),"000") -> Web-LGBB-021 | H31: 中 | I31: 正常系 | J31: 航站代码模糊查询校验 | K31: 1.总部人员身份 2.转到离岗报备查询界面 | L31: 1.输入航站代码 2.点击搜索 | M31: P | N31: 筛选记录的航站开头都与和测试数据相同
B32: =SUBTOTAL(103,$C$11:C32) -> 22 | C32: =测试大纲!$A$13 -> 3 | D32: 报备管理 | E32: 离岗报备 | F32: 离岗报备查询 | G32: =$D$9 & "-"&测试大纲!I$13&"-"&TEXT(SUBTOTAL(103,$C$11:C32),"000") -> Web-LGBB-022 | H32: 低 | I32: 正常系 | J32: 搜索结果数量统计是否正确 | K32: 1.总部人员身份 2.转到离岗报备查询界面 | L32: 1.输入航站代码 2.点击搜索 | M32: PEK | N32: 显示的结果数与标签“共搜索到X条数据”中的X相等
B33: =SUBTOTAL(103,$C$11:C33) -> 23 | C33: =测试大纲!$A$13 -> 3 | D33: 报备管理 | E33: 离岗报备 | F33: 离岗报备查询 | G33: =$D$9 & "-"&测试大纲!I$13&"-"&TEXT(SUBTOTAL(103,$C$11:C33),"000") -> Web-LGBB-023 | H33: 高 | I33: 异常系 | J33: 离岗时间长度异常校验 | K33: 1.总部人员身份 2.转到离岗报备查询界面 | L33: 1.输入离岗时间 2.点击搜索 | M33: 2017-12-11~2017-11-12 | N33: 弹出相关提示并且查询无效
B34: =SUBTOTAL(103,$C$11:C34) -> 24 | C34: =测试大纲!$A$13 -> 3 | D34: 报备管理 | E34: 离岗报备 | F34: 离岗报备查询 | G34: =$D$9 & "-"&测试大纲!I$13&"-"&TEXT(SUBTOTAL(103,$C$11:C34),"000") -> Web-LGBB-024 | H34: 高 | I34: 正常系 | J34: 未审批报备删除功能有效性校验 | K34: 1.总部人员身份 2.转到离岗报备查询界面 | L34: 1.选择一条未审批报备数据 2.点击删除 | N34: 该条数据从页面消失并且刷新页面后不再出现
B35: =SUBTOTAL(103,$C$11:C35) -> 25 | C35: =测试大纲!$A$13 -> 3 | D35: 报备管理 | E35: 离岗报备 | F35: 离岗报备查询 | G35: =$D$9 & "-"&测试大纲!I$13&"-"&TEXT(SUBTOTAL(103,$C$11:C35),"000") -> Web-LGBB-025 | H35: 高 | I35: 正常系 | J35: 已同意报备删除功能有效性校验 | K35: 1.总部人员身份 2.转到离岗报备查询界面 | L35: 1.选择一条已同意报备数据 2.点击删除 | N35: 该条数据从页面消失并且刷新页面后不再出现
B36: =SUBTOTAL(103,$C$11:C36) -> 26 | C36: =测试大纲!$A$13 -> 3 | D36: 报备管理 | E36: 离岗报备 | F36: 离岗报备查询 | G36: =$D$9 & "-"&测试大纲!I$13&"-"&TEXT(SUBTOTAL(103,$C$11:C36),"000") -> Web-LGBB-026 | H36: 高 | I36: 正常系 | J36: 已拒绝报备删除功能有效性校验 | K36: 1.总部人员身份 2.转到离岗报备查询界面 | L36: 1.选择一条已拒绝报备数据 2.点击删除 | N36: 该条数据从页面消失并且刷新页面后不再出现
B37: =SUBTOTAL(103,$C$11:C37) -> 27 | C37: =测试大纲!$A$13 -> 3 | D37: 报备管理 | E37: 离岗报备 | F37: 离岗报备查询 | G37: =$D$9 & "-"&测试大纲!I$13&"-"&TEXT(SUBTOTAL(103,$C$11:C37),"000") -> Web-LGBB-027 | H37: 高 | I37: 正常系 | J37: 详情查看功能有效性校验 | K37: 1.总部人员身份 2.转到离岗报备查询界面 | L37: 1.选择一条报备数据 2.点击查看 | N37: 除了关闭按钮其他元素锁定无法操作，页面元素如下： 1.文本框：员工号、中文姓名、外文姓名、所属航站、事由、离岗后联系电话、离岗后联系邮箱、离岗后站点负责人联系电话、离岗后站点负责人邮箱 2.勾选框：航展内部已审批通过 3.按钮：搜索、离岗报备 4.下拉框：负责人 5.日期控件：离岗时间 6.标签：填报人
B38: =SUBTOTAL(103,$C$11:C38) -> 28 | C38: =测试大纲!$A$13 -> 3 | D38: 报备管理 | E38: 离岗报备 | F38: 离岗报备查询 | G38: =$D$9 & "-"&测试大纲!I$13&"-"&TEXT(SUBTOTAL(103,$C$11:C38),"000") -> Web-LGBB-028 | H38: 中 | I38: 正常系 | J38: 校验航站代码能否自动转换大写 | K38: 1.总部人员身份 2.转到离岗报备查询界面 | L38: 1.输入航站 2.鼠标点击页面空白的地方 | M38: vvv | N38: VVV
B39: =SUBTOTAL(103,$C$11:C39) -> 29 | C39: =测试大纲!$A$13 -> 3 | D39: 报备管理 | E39: 离岗报备 | F39: 离岗报备查询 | G39: =$D$9 & "-"&测试大纲!I$13&"-"&TEXT(SUBTOTAL(103,$C$11:C39),"000") -> Web-LGBB-029 | H39: 低 | I39: 正常系 | J39: 校验航站代码含数字时是否能够查询 | K39: 1.总部人员身份 2.转到离岗报备查询界面 | L39: 1.输入航站 2.点击搜索 | M39: PEK123 | N39: 弹出相关提示并且查询无效
B40: =SUBTOTAL(103,$C$11:C40) -> 30 | C40: =测试大纲!$A$13 -> 3 | D40: 报备管理 | E40: 离岗报备 | F40: 离岗报备查询 | G40: =$D$9 & "-"&测试大纲!I$13&"-"&TEXT(SUBTOTAL(103,$C$11:C40),"000") -> Web-LGBB-030 | H40: 低 | I40: 正常系 | J40: 校验航站代码含特殊字符时是否能够查询 | K40: 1.总部人员身份 2.转到离岗报备查询界面 | L40: 1.输入航站 2.点击搜索 | M40: PEK，。、 | N40: 弹出相关提示并且查询无效
B41: =SUBTOTAL(103,$C$11:C41) -> 31 | C41: =测试大纲!$A$13 -> 3 | D41: 报备管理 | E41: 离岗报备 | F41: 离岗报备查询 | G41: =$D$9 & "-"&测试大纲!I$13&"-"&TEXT(SUBTOTAL(103,$C$11:C41),"000") -> Web-LGBB-031 | H41: 低 | I41: 正常系 | J41: 校验航站代码含中文时是否能够查询 | K41: 1.总部人员身份 2.转到离岗报备查询界面 | L41: 1.输入航站 2.点击搜索 | M41: PEK北京 | N41: 弹出相关提示并且查询无效
B42: =SUBTOTAL(103,$C$11:C42) -> 32 | C42: =测试大纲!$A$13 -> 3 | D42: 报备管理 | E42: 离岗报备 | F42: 离岗报备查询 | G42: =$D$9 & "-"&测试大纲!I$13&"-"&TEXT(SUBTOTAL(103,$C$11:C42),"000") -> Web-LGBB-032 | H42: 高 | I42: 正常系 | J42: 校验点击页面页码翻页的功能是否有效 | K42: 1.总部人员身份 2.转到离岗报备查询界面 3.存在三页及以上记录 | L42: 1.点击"2"尝试跳转到第二页 | N42: 跳转到第二页，当前页码为2
...

Sheet 运行月报告
B2: 测试用例
S4: 第1轮 | W4: 第2轮 | AA4: 第N轮
S5: 用例条数 | T5: =SUMPRODUCT(($G$11:$G$1875<>"")*($Q$11:$Q$1874<>"删除")) -> #N/A | U5: OK | V5: =SUMPRODUCT(($R$11:$R$1671="是")*(S$11:S$1671=U$5)) -> 0 | W5: 用例条数 | X5: {=SUMPRODUCT(($G$11:$G$1875<>"")*($Q$11:$Q$1874<>"删除"))} -> #N/A | Y5: OK | Z5: =SUMPRODUCT(($R$11:$R$1671="是")*(W$11:W$1671=Y$5)) -> 0 | AA5: 用例条数 | AB5: {=SUMPRODUCT(($G$11:$G$1875<>"")*($Q$11:$Q$1874<>"删除"))} -> #N/A | AC5: OK | AD5: =SUMPRODUCT(($R$11:$R$1671="是")*(AA$11:AA$1671=AC$5)) -> 0
S6: 纳入测试 | T6: {=COUNTIF($R$10:$R$1671,"是")} -> 3 | U6: POK | V6: =SUMPRODUCT(($R$11:$R$1671="是")*(S$11:S$1671=U$6)) -> 0 | W6: 纳入测试 | X6: {=COUNTIF($R$10:$R$1671,"是")} -> 3 | Y6: POK | Z6: =SUMPRODUCT(($R$11:$R$1671="是")*(W$11:W$1671=Y$6)) -> 0 | AA6: 纳入测试 | AB6: {=COUNTIF($R$10:$R$1671,"是")} -> 3 | AC6: POK | AD6: =SUMPRODUCT(($R$11:$R$1671="是")*(AA$11:AA$1671=AC$6)) -> 0
S7: 执行率 | T7: =IF(V5+V6+V7=0,0%,(V5+V6+V7)/(T6)) -> 0 | U7: NG | V7: =SUMPRODUCT(($R$11:$R$1671="是")*(S$11:S$1671=U$7)) -> 0 | W7: 执行率 | X7: =IF(Z5+Z6+Z7=0,0%,(Z5+Z6+Z7)/(X6)) -> 0 | Y7: NG | Z7: =SUMPRODUCT(($R$11:$R$1671="是")*(W$11:W$1671=Y$7)) -> 0 | AA7: 执行率 | AB7: =IF(AD5+AD6+AD7=0,0%,(AD5+AD6+AD7)/(AB6)) -> 0 | AC7: NG | AD7: =SUMPRODUCT(($R$11:$R$1671="是")*(AA$11:AA$1671=AC$7)) -> 0
D8: 测试标识 | E8: 所属项目 | F8: 子系统 | G8: 设计人员 | S8: 通过率 | T8: {=IF(V5=0,0%,V5/(V5+V6+V7))} -> 0 | U8: SKIP | V8: =SUMPRODUCT(($R$11:$R$1671="是")*(S$11:S$1671=U$8)) -> 0 | W8: 通过率 | X8: {=IF(Z5=0,0%,Z5/(Z5+Z6+Z7))} -> 0 | Y8: SKIP | Z8: =SUMPRODUCT(($R$11:$R$1671="是")*(W$11:W$1671=Y$8)) -> 0 | AA8: 通过率 | AB8: {=IF(AD5=0,0%,AD5/(AD5+AD6+AD7))} -> 0 | AC8: SKIP | AD8: =SUMPRODUCT(($R$11:$R$1671="是")*(AA$11:AA$1671=AC$8)) -> 0
D9: Web | E9: 航站二期 | G9: 袁国军 | S9: NT | T9: {=SUMPRODUCT(($R$11:$R$1671="是")*(S$11:S$1671=S9))} -> 0 | U9: 队列中 | V9: {=(T6-V8-V7-V6-V5-T9)} -> 3 | W9: NT | X9: {=SUMPRODUCT(($R$11:$R$1671="是")*(W$11:W$1671=W9))} -> 0 | Y9: 队列中 | Z9: {=(X6-Z8-Z7-Z6-Z5-X9)} -> 3 | AA9: NT | AB9: {=SUMPRODUCT(($R$11:$R$1671="是")*(AA$11:AA$1671=AA9))} -> 0 | AC9: 队列中 | AD9: {=(AB6-AD8-AD7-AD6-AD5-AB9)} -> 3
B10: 序号 | C10: 模块编号 | D10: 一级模块 | E10: 二级模块 | F10: 三级模块 | G10: 用例编号 | H10: 优先级 | I10: 分类 | J10: 用例描述 | K10: 前置条件 | L10: 测试方法和步骤 | M10: 测试数据 | N10: 预期结果 | O10: 验证过程 | P10: 测试工具 | Q10: 修订状态 | R10: 纳入测试 | S10: 测试结果 | T10: 测试版本 | U10: 测试人 | V10: 备注 | W10: 测试结果 | X10: 测试版本 | Y10: 测试人 | Z10: 备注 | AA10: 测试结果 | AB10: 测试版本 | AC10: 测试人 | AD10: 备注 | AE10: 导入结果
B11: =SUBTOTAL(103,$C$11:C11) -> 1 | C11: =测试大纲!$A$19 -> 4 | D11: 运行月报告 | E11: 运行月报告查询 | G11: =$D$9 & "-"&测试大纲!I$19&"-"&TEXT(SUBTOTAL(103,$C$11:C11),"000") -> Web-BGCX-001 | H11: 高 | I11: 正常系 | J11: 界面元素完整性校验 | K11: 1.总部人员身份 2.进入运行月报告查询界面 | N11: 页面元素如下: 1.文本框：航站 2.勾选框：未上报 3.按钮：搜索、导出 4.数据区显示列：航站、月份、运行月报告、上报时间、上报人、操作 5.数据区按钮：查看、删除 6.日期控件：日期 7.翻页控件 8.标签：共搜索到X到数据
B12: =SUBTOTAL(103,$C$11:C12) -> 2 | C12: =测试大纲!$A$19 -> 4 | D12: 运行月报告 | E12: 运行月报告查询 | G12: =$D$9 & "-"&测试大纲!I$19&"-"&TEXT(SUBTOTAL(103,$C$11:C12),"000") -> Web-BGCX-002 | H12: 高 | I12: 正常系 | J12: 页面默认数据正确性校验 | K12: 1.总部人员身份 2.进入运行月报告查询界面 | N12: 页面所有输入框数据为空、数据展示区也为空并且页码为1
B13: =SUBTOTAL(103,$C$11:C13) -> 3 | C13: =测试大纲!$A$19 -> 4 | D13: 运行月报告 | E13: 运行月报告查询 | G13: =$D$9 & "-"&测试大纲!I$19&"-"&TEXT(SUBTOTAL(103,$C$11:C13),"000") -> Web-BGCX-003 | H13: 高 | I13: 正常系 | J13: 默认查询正确性校验 | K13: 1.总部人员身份 2.进入运行月报告查询界面 | L13: 1.点击“搜索” | N13: 筛选出两年内的运行月报告
B14: =SUBTOTAL(103,$C$11:C14) -> 4 | C14: =测试大纲!$A$19 -> 4 | D14: 运行月报告 | E14: 运行月报告查询 | G14: =$D$9 & "-"&测试大纲!I$19&"-"&TEXT(SUBTOTAL(103,$C$11:C14),"000") -> Web-BGCX-004 | H14: 低 | I14: 正常系 | J14: 搜索结果数量统计是否正确 | K14: 1.总部人员身份 2.进入运行月报告查询界面 | L14: 1.输入航站代码 2.点击搜索 | M14: PEK | N14: 显示的结果数与标签“共搜索到X条数据”中的X相等
B15: =SUBTOTAL(103,$C$11:C15) -> 5 | C15: =测试大纲!$A$19 -> 4 | D15: 运行月报告 | E15: 运行月报告查询 | G15: =$D$9 & "-"&测试大纲!I$19&"-"&TEXT(SUBTOTAL(103,$C$11:C15),"000") -> Web-BGCX-005 | H15: 高 | I15: 正常系 | J15: 单条件航站查询正确性校验 | K15: 1.总部人员身份 2.进入运行月报告查询界面 | L15: 1.输入航站代码 2.点击“搜索” | M15: CAN | N15: 筛选出对应航站所有的离岗报备
B16: =SUBTOTAL(103,$C$11:C16) -> 6 | C16: =测试大纲!$A$19 -> 4 | D16: 运行月报告 | E16: 运行月报告查询 | G16: =$D$9 & "-"&测试大纲!I$19&"-"&TEXT(SUBTOTAL(103,$C$11:C16),"000") -> Web-BGCX-006 | H16: 高 | I16: 正常系 | J16: 单条件未上报询正确性校验 | K16: 1.总部人员身份 2.进入运行月报告查询界面 | L16: 1.勾选未上报 2.点击“搜索” | N16: 筛选出对应员工所有的离岗报备
B17: =SUBTOTAL(103,$C$11:C17) -> 7 | C17: =测试大纲!$A$19 -> 4 | D17: 运行月报告 | E17: 运行月报告查询 | G17: =$D$9 & "-"&测试大纲!I$19&"-"&TEXT(SUBTOTAL(103,$C$11:C17),"000") -> Web-BGCX-007 | H17: 高 | I17: 正常系 | J17: 单条件日期查询正确性校验 | K17: 1.总部人员身份 2.进入运行月报告查询界面 | L17: 1.选择日期 2.点击“搜索” | M17: 2018-02-05~2018-02-11 | N17: 筛选出对应员工所有的离岗报备
B18: =SUBTOTAL(103,$C$11:C18) -> 8 | C18: =测试大纲!$A$19 -> 4 | D18: 运行月报告 | E18: 运行月报告查询 | G18: =$D$9 & "-"&测试大纲!I$19&"-"&TEXT(SUBTOTAL(103,$C$11:C18),"000") -> Web-BGCX-008 | H18: 高 | I18: 异常系 | J18: 不存在航站查询校验 | K18: 1.总部人员身份 2.进入运行月报告查询界面 | L18: 1.输入航站代码 2.点击“搜索” | M18: ASX | N18: 数据展示区为空
B19: =SUBTOTAL(103,$C$11:C19) -> 9 | C19: =测试大纲!$A$19 -> 4 | D19: 运行月报告 | E19: 运行月报告查询 | G19: =$D$9 & "-"&测试大纲!I$19&"-"&TEXT(SUBTOTAL(103,$C$11:C19),"000") -> Web-BGCX-009 | H19: 中 | I19: 异常系 | J19: 单条件离岗时间长度异常查询 | K19: 1.总部人员身份 2.进入运行月报告查询界面 | L19: 1.输入离岗时间 2.点击“搜索” | M19: 2018-02-05~2018-01-11 | N19: 弹出相关提示
B20: =SUBTOTAL(103,$C$11:C20) -> 10 | C20: =测试大纲!$A$19 -> 4 | D20: 运行月报告 | E20: 运行月报告查询 | G20: =$D$9 & "-"&测试大纲!I$19&"-"&TEXT(SUBTOTAL(103,$C$11:C20),"000") -> Web-BGCX-010 | H20: 高 | I20: 正常系 | J20: 全条件查询正确性校验 | K20: 1.总部人员身份 2.进入运行月报告查询界面 | L20: 1.输入航站 2.选择日期 3.勾选未上报 4.点击“搜索” | M20: 1.CAN 2.2018-02-05~2018-03-11 | N20: 筛选出对应条件所有的离岗报备
B21: =SUBTOTAL(103,$C$11:C21) -> 11 | C21: =测试大纲!$A$19 -> 4 | D21: 运行月报告 | E21: 运行月报告查询 | G21: =$D$9 & "-"&测试大纲!I$19&"-"&TEXT(SUBTOTAL(103,$C$11:C21),"000") -> Web-BGCX-011 | H21: 高 | I21: 异常系 | J21: 单一航站不关联，其他全条件关联查询，校验是否会返回数据并给与相关提示 | K21: 1.总部人员身份 2.进入运行月报告查询界面 | L21: 1.输入航站 2.选择日期 3.勾选未上报 4.点击搜索 | M21: 1.PPL 2.2018-02-05~2018-03-11 | N21: 筛选记录数为0，并弹出相关提示
B22: =SUBTOTAL(103,$C$11:C22) -> 12 | C22: =测试大纲!$A$19 -> 4 | D22: 运行月报告 | E22: 运行月报告查询 | G22: =$D$9 & "-"&测试大纲!I$19&"-"&TEXT(SUBTOTAL(103,$C$11:C22),"000") -> Web-BGCX-012 | H22: 高 | I22: 异常系 | J22: 单一日期不关联，其他全条件关联查询，校验是否会返回数据并给与相关提示 | K22: 1.总部人员身份 2.进入运行月报告查询界面 | L22: 1.输入航站 2.选择日期 3.勾选未上报 4.点击搜索 | M22: 1.PEK 2.2018-10-11~2018-11-12 | N22: 筛选记录数为0，并弹出相关提示
B23: =SUBTOTAL(103,$C$11:C23) -> 13 | C23: =测试大纲!$A$19 -> 4 | D23: 运行月报告 | E23: 运行月报告查询 | G23: =$D$9 & "-"&测试大纲!I$19&"-"&TEXT(SUBTOTAL(103,$C$11:C23),"000") -> Web-BGCX-013 | H23: 高 | I23: 异常系 | J23: 单一未上报不关联，其他全条件关联查询，校验是否会返回数据并给与相关提示 | K23: 1.总部人员身份 2.进入运行月报告查询界面 | L23: 1.输入航站 2.选择日期 3.勾选未上报 4.点击搜索 | M23: 1.CAN 2.2018-02-05~2018-03-11 | N23: 筛选记录数为0，并弹出相关提示
B24: =SUBTOTAL(103,$C$11:C24) -> 14 | C24: =测试大纲!$A$19 -> 4 | D24: 运行月报告 | E24: 运行月报告查询 | G24: =$D$9 & "-"&测试大纲!I$19&"-"&TEXT(SUBTOTAL(103,$C$11:C24),"000") -> Web-BGCX-014 | H24: 高 | I24: 正常系 | J24: 导出功能正确性校验 | K24: 1.总部人员身份 2.进入运行月报告查询界面 | L24: 1.点击“搜索” 2.点击“导出” | N24: 文件格式为Excel，内容与数据展示区内容一致
B25: =SUBTOTAL(103,$C$11:C25) -> 15 | C25: =测试大纲!$A$19 -> 4 | D25: 运行月报告 | E25: 运行月报告查询 | G25: =$D$9 & "-"&测试大纲!I$19&"-"&TEXT(SUBTOTAL(103,$C$11:C25),"000") -> Web-BGCX-015 | H25: 高 | I25: 正常系 | J25: 导出功能覆盖可用性校验 | K25: 1.总部人员身份 2.进入运行月报告查询界面 | L25: 1.点击“搜索” 2.点击“导出” 3.点击“确定”弹出覆盖提示 4.点击“确定” | N25: 提示覆盖成功，文件内容与先导出数据一致
B26: =SUBTOTAL(103,$C$11:C26) -> 16 | C26: =测试大纲!$A$19 -> 4 | D26: 运行月报告 | E26: 运行月报告查询 | G26: =$D$9 & "-"&测试大纲!I$19&"-"&TEXT(SUBTOTAL(103,$C$11:C26),"000") -> Web-BGCX-016 | H26: 高 | I26: 正常系 | J26: 航站代码自动转换大写有效性校验 | K26: 1.总部人员身份 2.进入运行月报告查询界面 | L26: 1.输入航站 2.鼠标点击页面空白的地方 | M26: 航站代码：pek | N26: 航站代码：PEK
B27: =SUBTOTAL(103,$C$11:C27) -> 17 | C27: =测试大纲!$A$19 -> 4 | D27: 运行月报告 | E27: 运行月报告查询 | G27: =$D$9 & "-"&测试大纲!I$19&"-"&TEXT(SUBTOTAL(103,$C$11:C27),"000") -> Web-BGCX-017 | H27: 低 | I27: 正常系 | J27: 校验航站代码含数字时是否能够查询 | K27: 1.总部人员身份 2.进入运行月报告查询界面 | L27: 1.输入航站 2.点击搜索 | M27: PEK123 | N27: 弹出相关提示并且查询无效
B28: =SUBTOTAL(103,$C$11:C28) -> 18 | C28: =测试大纲!$A$19 -> 4 | D28: 运行月报告 | E28: 运行月报告查询 | G28: =$D$9 & "-"&测试大纲!I$19&"-"&TEXT(SUBTOTAL(103,$C$11:C28),"000") -> Web-BGCX-018 | H28: 低 | I28: 正常系 | J28: 校验航站代码含特殊字符时是否能够查询 | K28: 1.总部人员身份 2.进入运行月报告查询界面 | L28: 1.输入航站 2.点击搜索 | M28: PEK，。、 | N28: 弹出相关提示并且查询无效
B29: =SUBTOTAL(103,$C$11:C29) -> 19 | C29: =测试大纲!$A$19 -> 4 | D29: 运行月报告 | E29: 运行月报告查询 | G29: =$D$9 & "-"&测试大纲!I$19&"-"&TEXT(SUBTOTAL(103,$C$11:C29),"000") -> Web-BGCX-019 | H29: 低 | I29: 正常系 | J29: 校验航站代码含中文时是否能够查询 | K29: 1.总部人员身份 2.进入运行月报告查询界面 | L29: 1.输入航站 2.点击搜索 | M29: PEK北京 | N29: 弹出相关提示并且查询无效
B30: =SUBTOTAL(103,$C$11:C30) -> 20 | C30: =测试大纲!$A$19 -> 4 | D30: 运行月报告 | E30: 运行月报告查询 | G30: =$D$9 & "-"&测试大纲!I$19&"-"&TEXT(SUBTOTAL(103,$C$11:C30),"000") -> Web-BGCX-020 | H30: 高 | I30: 正常系 | J30: 航站代码模糊查询可用性校验 | K30: 1.总部人员身份 2.进入运行月报告查询界面 | L30: 1.输入航站 | M30: 航站代码：pv | N30: 查询出所有PV开头的航站节假日
B31: =SUBTOTAL(103,$C$11:C31) -> 21 | C31: =测试大纲!$A$19 -> 4 | D31: 运行月报告 | E31: 运行月报告查询 | G31: =$D$9 & "-"&测试大纲!I$19&"-"&TEXT(SUBTOTAL(103,$C$11:C31),"000") -> Web-BGCX-021 | H31: 高 | I31: 正常系 | J31: 详情查看功能正确性校验 | K31: 1.总部人员身份 2.进入运行月报告查询界面 | L31: 1.点击查看 | N31: 进入月报告详情查看页面，页面内容格式与添加月报告格式一致并且部分内容与页面展示数据一致
B32: =SUBTOTAL(103,$C$11:C32) -> 22 | C32: =测试大纲!$A$19 -> 4 | D32: 运行月报告 | E32: 运行月报告查询 | G32: =$D$9 & "-"&测试大纲!I$19&"-"&TEXT(SUBTOTAL(103,$C$11:C32),"000") -> Web-BGCX-022 | H32: 中 | I32: 正常系 | J32: 删除运行月报告校验 | K32: 1.总部人员身份 2.进入运行月报告查询界面 | L32: 1.删除一条数据 | N32: 记录被删除并且刷新页面后该数据消失
B33: =SUBTOTAL(103,$C$11:C33) -> 23 | C33: =测试大纲!$A$19 -> 4 | D33: 运行月报告 | E33: 运行月报告查询 | G33: =$D$9 & "-"&测试大纲!I$19&"-"&TEXT(SUBTOTAL(103,$C$11:C33),"000") -> Web-BGCX-023 | H33: 高 | I33: 正常系 | J33: 页码点击翻页正确性校验 | K33: 1.总部人员身份 2.进入运行月报告查询界面 3.存在三页及以上记录 | L33: 1.点击"2"跳转到第二页 | N33: 跳转到第二页，当前页码为2
B34: =SUBTOTAL(103,$C$11:C34) -> 24 | C34: =测试大纲!$A$19 -> 4 | D34: 运行月报告 | E34: 运行月报告查询 | G34: =$D$9 & "-"&测试大纲!I$19&"-"&TEXT(SUBTOTAL(103,$C$11:C34),"000") -> Web-BGCX-024 | H34: 高 | I34: 正常系 | J34: 页面跳转到指定页码正确性校验 | K34: 1.总部人员身份 2.进入运行月报告查询界面 3.存在三页及以上记录 | L34: 1.输入页码 2.回车 | M34: 2 | N34: 跳转到第二页，当前页码为2
B35: =SUBTOTAL(103,$C$11:C35) -> 25 | C35: =测试大纲!$A$19 -> 4 | D35: 运行月报告 | E35: 运行月报告查询 | G35: =$D$9 & "-"&测试大纲!I$19&"-"&TEXT(SUBTOTAL(103,$C$11:C35),"000") -> Web-BGCX-025 | H35: 高 | I35: 正常系 | J35: 页面跳转至上一页正确性校验 | K35: 1.总部人员身份 2.进入运行月报告查询界面 3.存在三页及以上记录 | L35: 1.跳转至第二页 2.点击上一页图标“<” | N35: 跳转至第一页，当前页码为1
B36: =SUBTOTAL(103,$C$11:C36) -> 26 | C36: =测试大纲!$A$19 -> 4 | D36: 运行月报告 | E36: 运行月报告查询 | G36: =$D$9 & "-"&测试大纲!I$19&"-"&TEXT(SUBTOTAL(103,$C$11:C36),"000") -> Web-BGCX-026 | H36: 高 | I36: 正常系 | J36: 页面跳转至下一页正确性校验 | K36: 1.总部人员身份 2.进入运行月报告查询界面 3.存在三页及以上记录 | L36: 1.点击下一页图标“>” | N36: 跳转至第二页，当前页码为2
B37: =SUBTOTAL(103,$C$11:C37) -> 27 | C37: =测试大纲!$A$19 -> 4 | D37: 运行月报告 | E37: 运行月报告查询 | G37: =$D$9 & "-"&测试大纲!I$19&"-"&TEXT(SUBTOTAL(103,$C$11:C37),"000") -> Web-BGCX-027 | H37: 高 | I37: 异常系 | J37: 错误页码跳转校验 | K37: 1.总部人员身份 2.进入运行月报告查询界面 3.存在三页及以上记录 | L37: 1.输入页码 2.回车 | M37: 0 | N37: 提示输入页码输入有误
B38: =SUBTOTAL(103,$C$11:C38) -> 28 | C38: =测试大纲!$A$19 -> 4 | D38: 运行月报告 | E38: 运行月报告查询 | G38: =$D$9 & "-"&测试大纲!I$19&"-"&TEXT(SUBTOTAL(103,$C$11:C38),"000") -> Web-BGCX-028 | H38: 高 | I38: 正常系 | J38: 页面记录数正确性校验 | K38: 1.总部人员身份 2.进入运行月报告查询界面 3.存在三页及以上记录 | N38: 页面记录显示数量为20条
B39: =SUBTOTAL(103,$C$11:C39) -> 29 | C39: =测试大纲!$A$19 -> 4 | D39: 运行月报告 | E39: 运行月报告查询 | G39: =$D$9 & "-"&测试大纲!I$19&"-"&TEXT(SUBTOTAL(103,$C$11:C39),"000") -> Web-BGCX-029 | H39: 高 | I39: 正常系 | J39: 跳转页面后页面记录数正确性校验 | K39: 1.总部人员身份 2.进入运行月报告查询界面 3.存在三页及以上记录 | L39: 1.点击下一页图标 | N39: 页面记录显示数量为20条
B40: =SUBTOTAL(103,$C$11:C40) -> 30 | C40: =测试大纲!$A$19 -> 4 | D40: 运行月报告 | E40: 运行月报告查询 | G40: =$D$9 & "-"&测试大纲!I$19&"-"&TEXT(SUBTOTAL(103,$C$11:C40),"000") -> Web-BGCX-030 | H40: 高 | I40: 正常系 | J40: 跳转页面后查询条件正确性校验 | K40: 1.总部人员身份 2.进入运行月报告查询界面 3.存在三页及以上记录 | L40: 1.输入航站 2.点击搜索 3.点击下一页 | M40: PEK | N40: 搜索条件框数据不变，页面记录的航站都与测试数据相同
B41: =SUBTOTAL(103,$C$11:C41) -> 31 | C41: =测试大纲!$A$19 -> 4 | D41: 运行月报告 | E41: 运行月报告查询 | G41: =$D$9 & "-"&测试大纲!I$19&"-"&TEXT(SUBTOTAL(103,$C$11:C41),"000") -> Web-BGCX-031 | H41: 高 | I41: 正常系 | J41: 校验跳转页面后页码显示数量是否不变 | K41: 1.总部人员身份 2.进入运行月报告查询界面 3.存在三页及以上记录 | L41: 1.点击搜索 2.点击下一页 | N41: 跳转后的页码显示数量与跳转前相同
B42: =SUBTOTAL(103,$C$11:C42) -> 32 | C42: =测试大纲!$A$19 -> 4 | D42: 运行月报告 | E42: 运行月报告查询 | G42: =$D$9 & "-"&测试大纲!I$19&"-"&TEXT(SUBTOTAL(103,$C$11:C42),"000") -> Web-BGCX-032 | H42: 高 | I42: 异常系 | J42: 校验搜索后改变查询条件再次搜索是否是在现有结果中查询 | K42: 1.总部人员身份 2.进入运行月报告查询界面 3.存在三页及以上记录 | L42: 1.输入航站 2.点击搜索 3.修改航站 4.点击搜索 | M42: 1.PEK 2.CAN | N42: 不从现有结果中搜索而是从总数据中搜索结果
...

Sheet 通讯录
B2: 测试用例
S4: 第1轮 | W4: 第2轮 | AA4: 第N轮
S5: 用例条数 | T5: =SUMPRODUCT(($G$11:$G$1808<>"")*($Q$11:$Q$1807<>"删除")) -> #N/A | U5: OK | V5: =SUMPRODUCT(($R$11:$R$1604="是")*(S$11:S$1604=U$5)) -> 0 | W5: 用例条数 | X5: {=SUMPRODUCT(($G$11:$G$1808<>"")*($Q$11:$Q$1807<>"删除"))} -> #N/A | Y5: OK | Z5: =SUMPRODUCT(($R$11:$R$1604="是")*(W$11:W$1604=Y$5)) -> 0 | AA5: 用例条数 | AB5: {=SUMPRODUCT(($G$11:$G$1808<>"")*($Q$11:$Q$1807<>"删除"))} -> #N/A | AC5: OK | AD5: =SUMPRODUCT(($R$11:$R$1604="是")*(AA$11:AA$1604=AC$5)) -> 0
S6: 纳入测试 | T6: {=COUNTIF($R$10:$R$1604,"是")} -> 3 | U6: POK | V6: =SUMPRODUCT(($R$11:$R$1604="是")*(S$11:S$1604=U$6)) -> 0 | W6: 纳入测试 | X6: {=COUNTIF($R$10:$R$1604,"是")} -> 3 | Y6: POK | Z6: =SUMPRODUCT(($R$11:$R$1604="是")*(W$11:W$1604=Y$6)) -> 0 | AA6: 纳入测试 | AB6: {=COUNTIF($R$10:$R$1604,"是")} -> 3 | AC6: POK | AD6: =SUMPRODUCT(($R$11:$R$1604="是")*(AA$11:AA$1604=AC$6)) -> 0
S7: 执行率 | T7: =IF(V5+V6+V7=0,0%,(V5+V6+V7)/(T6)) -> 0 | U7: NG | V7: =SUMPRODUCT(($R$11:$R$1604="是")*(S$11:S$1604=U$7)) -> 0 | W7: 执行率 | X7: =IF(Z5+Z6+Z7=0,0%,(Z5+Z6+Z7)/(X6)) -> 0 | Y7: NG | Z7: =SUMPRODUCT(($R$11:$R$1604="是")*(W$11:W$1604=Y$7)) -> 0 | AA7: 执行率 | AB7: =IF(AD5+AD6+AD7=0,0%,(AD5+AD6+AD7)/(AB6)) -> 0 | AC7: NG | AD7: =SUMPRODUCT(($R$11:$R$1604="是")*(AA$11:AA$1604=AC$7)) -> 0
D8: 测试标识 | E8: 所属项目 | F8: 子系统 | G8: 设计人员 | S8: 通过率 | T8: {=IF(V5=0,0%,V5/(V5+V6+V7))} -> 0 | U8: SKIP | V8: =SUMPRODUCT(($R$11:$R$1604="是")*(S$11:S$1604=U$8)) -> 0 | W8: 通过率 | X8: {=IF(Z5=0,0%,Z5/(Z5+Z6+Z7))} -> 0 | Y8: SKIP | Z8: =SUMPRODUCT(($R$11:$R$1604="是")*(W$11:W$1604=Y$8)) -> 0 | AA8: 通过率 | AB8: {=IF(AD5=0,0%,AD5/(AD5+AD6+AD7))} -> 0 | AC8: SKIP | AD8: =SUMPRODUCT(($R$11:$R$1604="是")*(AA$11:AA$1604=AC$8)) -> 0
D9: Web | E9: 航站二期 | G9: 袁国军 | S9: NT | T9: {=SUMPRODUCT(($R$11:$R$1604="是")*(S$11:S$1604=S9))} -> 0 | U9: 队列中 | V9: {=(T6-V8-V7-V6-V5-T9)} -> 3 | W9: NT | X9: {=SUMPRODUCT(($R$11:$R$1604="是")*(W$11:W$1604=W9))} -> 0 | Y9: 队列中 | Z9: {=(X6-Z8-Z7-Z6-Z5-X9)} -> 3 | AA9: NT | AB9: {=SUMPRODUCT(($R$11:$R$1604="是")*(AA$11:AA$1604=AA9))} -> 0 | AC9: 队列中 | AD9: {=(AB6-AD8-AD7-AD6-AD5-AB9)} -> 3
B10: 序号 | C10: 模块编号 | D10: 一级模块 | E10: 二级模块 | F10: 三级模块 | G10: 用例编号 | H10: 优先级 | I10: 分类 | J10: 用例描述 | K10: 前置条件 | L10: 测试方法和步骤 | M10: 测试数据 | N10: 预期结果 | O10: 验证过程 | P10: 测试工具 | Q10: 修订状态 | R10: 纳入测试 | S10: 测试结果 | T10: 测试版本 | U10: 测试人 | V10: 备注 | W10: 测试结果 | X10: 测试版本 | Y10: 测试人 | Z10: 备注 | AA10: 测试结果 | AB10: 测试版本 | AC10: 测试人 | AD10: 备注 | AE10: 导入结果
B11: =SUBTOTAL(103,$C11:C$11) -> 1 | C11: =测试大纲!$A$24 -> 5 | D11: 通讯录 | E11: 通讯录操作 | G11: =报备管理!$D$9 & "-"&测试大纲!I$24&"-"&TEXT(SUBTOTAL(103,$C11:C$11),"000") -> Web-TXCZ-001 | H11: 高 | I11: 正常系 | J11: 下载有效性校验 | K11: 1.航站人员身份 2.进入通讯录界面 | L11: 1.点击“下载” 2.选择路径 3.点击“确定” | N11: 将通讯录下载到指定路径打开无错误
B12: =SUBTOTAL(103,$C$11:C12) -> 2 | C12: =测试大纲!$A$24 -> 5 | D12: 通讯录 | E12: 通讯录操作 | G12: =报备管理!$D$9 & "-"&测试大纲!I$24&"-"&TEXT(SUBTOTAL(103,$C$11:C12),"000") -> Web-TXCZ-002 | H12: 高 | I12: 异常系 | J12: 下载覆盖有效性校验 | K12: 1.航站人员身份 2.进入通讯录界面 | L12: 1.点击“下载” 2.选择路径 3.点击“确定”，弹出覆盖选择框 4.点击确定 | M12: 路径下存在同名文件 | N12: 覆盖路径下存在的同名文件
B13: =SUBTOTAL(103,$C$11:C13) -> 3 | C13: =测试大纲!$A$24 -> 5 | D13: 通讯录 | E13: 通讯录操作 | G13: =报备管理!$D$9 & "-"&测试大纲!I$24&"-"&TEXT(SUBTOTAL(103,$C$11:C13),"000") -> Web-TXCZ-003 | H13: 高 | I13: 正常系 | J13: 上传有效性校验 | K13: 1.总部人员身份 2.进入通讯录界面 | L13: 1.点击“上传” 2.选择路径 3.点击“确定” 4.下载通讯录文件 | N13: 下载的通讯录文件与上传文件一致
B14: =SUBTOTAL(103,$C$11:C14) -> 4 | C14: =测试大纲!$A$24 -> 5 | D14: 通讯录 | E14: 通讯录操作 | G14: =报备管理!$D$9 & "-"&测试大纲!I$24&"-"&TEXT(SUBTOTAL(103,$C$11:C14),"000") -> Web-TXCZ-004 | H14: 高 | I14: 正常系 | J14: 上传覆盖有效性校验 | K14: 1.总部人员身份 2.进入通讯录界面 3.已存在上传的通讯录 | L14: 1.点击“上传” 2.选择路径 3.点击“确定” 4.下载通讯录文件 | N14: 下载的通讯录文件与刚刚上传文件一致
B15: =SUBTOTAL(103,$C$11:C15) -> 5 | C15: =测试大纲!$A$24 -> 5 | D15: 报备管理 | E15: 站内信 | G15: =报备管理!$D$9 & "-"&测试大纲!I$25&"-"&TEXT(SUBTOTAL(103,$C$15:C15),"000") -> Web-ZNXJ-001 | H15: 高 | I15: 正常系 | J15: 节假日报备提交成功后站内信提醒管理员校验 | K15: 1.总部人员身份 2.进入节假日值班报备添加界面 3.添加报备成功 | L15: 1.查看站内信是否存在相关提醒 | M15: 1.2017-10-9~2017-10-10 2.13829362187 3.422444109@qq.com | N15: 标题为XX航站XX（姓名）提交了节假日值班报备，
B16: =SUBTOTAL(103,$C$11:C16) -> 6 | C16: =测试大纲!$A$24 -> 5 | D16: 报备管理 | E16: 站内信 | G16: =报备管理!$D$9 & "-"&测试大纲!I$25&"-"&TEXT(SUBTOTAL(103,$C$15:C16),"000") -> Web-ZNXJ-002 | H16: 高 | I16: 正常系 | J16: 站内信提醒管理员详情查看校验 | K16: 1.总部人员身份 2.进入管理员站内信界面 3.存在至少一封站内信 | L16: 1.点击标题 | N16: 详情中通过表格列出具体的值班报备信息
B17: =SUBTOTAL(103,$C$11:C17) -> 7 | C17: =测试大纲!$A$24 -> 5 | D17: 报备管理 | E17: 站内信 | G17: =报备管理!$D$9 & "-"&测试大纲!I$25&"-"&TEXT(SUBTOTAL(103,$C$15:C17),"000") -> Web-ZNXJ-003 | H17: 高 | I17: 正常系 | J17: 校验未点击过的站内信状态 | K17: 1.总部人员身份 2.进入管理员站内信界面 3.存在至少一封未点击过的站内信 | N17: 未点击过的站内信为未读状态
B18: =SUBTOTAL(103,$C$11:C18) -> 8 | C18: =测试大纲!$A$24 -> 5 | D18: 报备管理 | E18: 站内信 | G18: =报备管理!$D$9 & "-"&测试大纲!I$25&"-"&TEXT(SUBTOTAL(103,$C$15:C18),"000") -> Web-ZNXJ-004 | H18: 高 | I18: 正常系 | J18: 校验点击过的站内信状态 | K18: 1.总部人员身份 2.进入管理员站内信界面 3.存在至少一封未读状态的站内信 | L18: 1.点击未读状态站内信的标题 | N18: 点击过的站内信为已读状态
R139: 是
R241: 是
R472: 是

Sheet 流程测试用例

Sheet 流程图

Sheet 流程测试用例示例
B2: 测试用例
J4: 第1轮 | N4: 第2轮 | R4: 第N轮
J5: 用例条数 | K5: =SUMPRODUCT(($B$11:$B$1704<>"")*($H$11:$H$1704<>"删除")) -> 6 | L5: OK | M5: =SUMPRODUCT(($I$11:$I$1501="是")*(J$11:J$1501=L$5)) -> 0 | N5: 用例条数 | O5: =SUMPRODUCT(($B$11:$B$1704<>"")*($H$11:$H$1704<>"删除")) -> 6 | P5: OK | Q5: =SUMPRODUCT(($I$11:$I$1501="是")*(N$11:N$1501=P$5)) -> 0 | R5: 用例条数 | S5: =SUMPRODUCT(($B$11:$B$1704<>"")*($H$11:$H$1704<>"删除")) -> 6 | T5: OK | U5: =SUMPRODUCT(($I$11:$I$1501="是")*(R$11:R$1501=T$5)) -> 0
J6: 纳入测试 | K6: {=COUNTIF($I$10:$I$1501,"是")} -> 0 | L6: POK | M6: =SUMPRODUCT(($I$11:$I$1501="是")*(J$11:J$1501=L$6)) -> 0 | N6: 纳入测试 | O6: {=COUNTIF($I$10:$I$1501,"是")} -> 0 | P6: POK | Q6: =SUMPRODUCT(($I$11:$I$1501="是")*(N$11:N$1501=P$6)) -> 0 | R6: 纳入测试 | S6: {=COUNTIF($I$10:$I$1501,"是")} -> 0 | T6: POK | U6: =SUMPRODUCT(($I$11:$I$1501="是")*(R$11:R$1501=T$6)) -> 0
J7: 执行率 | K7: =IF(M5+M6+M7=0,0%,(M5+M6+M7)/(K6)) -> 0 | L7: NG | M7: =SUMPRODUCT(($I$11:$I$1501="是")*(J$11:J$1501=L$7)) -> 0 | N7: 执行率 | O7: =IF(Q5+Q6+Q7=0,0%,(Q5+Q6+Q7)/(O6)) -> 0 | P7: NG | Q7: =SUMPRODUCT(($I$11:$I$1501="是")*(N$11:N$1501=P$7)) -> 0 | R7: 执行率 | S7: =IF(U5+U6+U7=0,0%,(U5+U6+U7)/(S6)) -> 0 | T7: NG | U7: =SUMPRODUCT(($I$11:$I$1501="是")*(R$11:R$1501=T$7)) -> 0
J8: 通过率 | K8: {=IF(M5=0,0%,M5/(M5+M6+M7))} -> 0 | L8: SKIP | M8: =SUMPRODUCT(($I$11:$I$1501="是")*(J$11:J$1501=L$8)) -> 0 | N8: 通过率 | O8: {=IF(Q5=0,0%,Q5/(Q5+Q6+Q7))} -> 0 | P8: SKIP | Q8: =SUMPRODUCT(($I$11:$I$1501="是")*(N$11:N$1501=P$8)) -> 0 | R8: 通过率 | S8: {=IF(U5=0,0%,U5/(U5+U6+U7))} -> 0 | T8: SKIP | U8: =SUMPRODUCT(($I$11:$I$1501="是")*(R$11:R$1501=T$8)) -> 0
J9: NT | K9: {=SUMPRODUCT(($I$11:$I$1501="是")*(J$11:J$1501=J9))} -> 0 | L9: 队列中 | M9: {=(K6-M8-M7-M6-M5-K9)} -> 0 | N9: NT | O9: {=SUMPRODUCT(($I$11:$I$1501="是")*(N$11:N$1501=N9))} -> 0 | P9: 队列中 | Q9: {=(O6-Q8-Q7-Q6-Q5-O9)} -> 0 | R9: NT | S9: {=SUMPRODUCT(($I$11:$I$1501="是")*(R$11:R$1501=R9))} -> 0 | T9: 队列中 | U9: {=(S6-U8-U7-U6-U5-S9)} -> 0
B10: 用例编号 | C10: 模块 | D10: 流程分类 | E10: 用例描述 | F10: 测试方法和步骤 | G10: 预期结果 | H10: 修订状态 | I10: 纳入测试 | J10: 测试结果 | K10: 测试版本 | L10: 测试人 | M10: 备注 | N10: 测试结果 | O10: 测试版本 | P10: 测试人 | Q10: 备注 | R10: 测试结果 | S10: 测试版本 | T10: 测试人 | U10: 备注
B11: TC-ST-SCM-UCM-流程测试-001 | C11: Defect | D11: 基本流程 | E11: 正常修改流程 | F11: 测试人员提交缺陷→开发人员接收缺陷→开发人员修改缺陷→测试人员验证关闭缺陷 | G11: 流程可以正常流转，流转时状态转换正确，从Submitted→Opened→Resolved→Closed 缺陷到达Closed状态后除增加注释外，不能对缺陷进行修改 | J11: OK
B12: TC-ST-SCM-UCM-流程测试-002 | D12: 基本流程 | E12: 修复失败流程 | F12: 测试人员提交缺陷→开发人员接收缺陷→开发人员修改缺陷→测试人员验证打回缺陷（Reject）→开发人员修复缺陷-测试人员验证关闭缺陷 （需验证测试人员多次验证打回缺陷的情况） | G12: 流程可以正常流转，流转时状态转换正确，从Submitted→Opened→Resolved→Opened→Resolved→Closed 缺陷到达Closed状态后除增加注释外，不能对缺陷进行修改 | J12: OK
B13: TC-ST-SCM-UCM-流程测试-003 | D13: 基本流程 | E13: 拒绝处理流程 | F13: ……
B14: TC-ST-SCM-UCM-流程测试-004 | D14: 备选流程 | E14: 分歧处理流程 | F14: ……
B15: TC-ST-SCM-UCM-流程测试-005 | D15: 备选流程 | E15: 延迟处理流程 | F15: ……
B16: TC-ST-SCM-UCM-流程测试-006 | E16: ……

Sheet 使用说明
B1: 使用说明：
B2: （一）、测试用例维护的原则
D3: 1、测试时，测试用例及测试大纲需要及时维护，保证一个系统有一份完整的功能测试用例。
E4: 每次生产变更需在这一份测试用例中选择部分测试用例作为执行对象。
D5: 2、原则上不允许物理删除测试用例，可使用“修订状态”列标记删除（标记后，会自动标记删除线）
D6: 3、测试用例编号要求唯一（含被标记为删除的用例）
B7: （二）、测试用例维护方法
D8: 操作 | K8: 详细
D9: 新增测试用例 | K9: 在对应的模块内增加测试用例，将其测试用例编号设置为该模块用例编号最大值+1，保证测试用例编号不重复（含被标记为删除的用例），并将【修订状态】属性设置为“新增”。
D10: 修改测试用例 | K10: 修改对应的测试用例，并将该条测试用例的【修订状态】属性设置为“修改”。
D11: 删除测试用例 | K11: 将测试用例的【修订状态】属性设定为“删除”，【纳入测试】属性设置为“否”。
B13: （三）、测试用例选取方法
D14: 测试用例选取遵循以下步骤：
D15: 1、获取上次生产变更所使用的测试用例。
D16: 2、清空所有测试用例的执行结果，注意每个标签页上的自动计算公式是否正常。
D17: 3、清空所有测试用例的“纳入测试”属性。
D18: 4、将前一次标记了“新增”、“修改”的用例的“修订状态”属性设置为空。
D19: 5、参考本文章节（二）对测试用例进行维护。
D20: 6、 | E20: 选择计划要执行的测试用例，将测试用例的“纳入测试”属性设定为“是”。
E21: 测试用例评审及测试用例执行将针对纳入测试的测试用例进行。
D22: 7、维护测试大纲（内容及测试用例数），清空【纳入测试数】列及【是否纳入测试】列。
D23: 8、将抽选了测试用例的模块的【是否纳入测试】属性设置为“√”，计算
E24: 模块中被纳入测试的用例数并填入【纳入测试数】属性中。
B25: （四）关于流程测试用例
D26: 对流程测试用例的模板不做要求，可根据系统具体情况设计流程测试用例格式，可参考“流程测试用例示例”
D27: 注意： | F27: （1）流程测试用例也需要有对应的编号，也要有测试结果记录。
F28: （2）测试用例编写完成后需将“流程测试用例示例”页删除。
B29: （五）FQA
D30: 1、测试用例结果统计的公式不小心被修改了怎么办？
E31: 答：可通过从模板拷贝粘贴的方式更新公式。
D32: 2、测试执行多个轮次时，结果统计中，前边轮次的纳入测试用例数等会跟随着后续的轮次改变怎么办？
E33: 答：每个轮次开始前，请将前一个轮次结果统计中的公式变为静态的数值。
F34: 方法为：选择需要变更区域，复制（ctrl+C），然后在被选区域上右键，选择“选择性粘贴”，
F35: 在对话框中选择“数值”后确定，则公式被替换为实际的数值。
B36: （六）优先级评定
D37: BVTs(Build Verification Tests):冒烟测试，最近1个月出现bug的用例
D38: 高（Highs）：最常执行以保证功能性是稳定的，目标的行为和能力可以正常的工作，和重要的错误和边界被测试的测试用例的集合。
D39: 中(Mediums)：这是使给出的功能区域或功能变得更详细，检查功能的多数方面包括边界，错误和配置测试的测试用例。
D40: 低(Lows)：这是通常最少被执行的测试用例。但这并不意味着这些测试都不重要，只是说他们在项目的生命期间里不是常常被运行，例如GUI，错误信息，可用性，压力和性能测试。
